2025-02-24 22:09:21,283 - __main__ - ERROR - Login failed: HTTPConnectionPool(host='localhost', port=8080): Max retries exceeded with url: /apis/broker/login/zerodha?action=login&type=login&status=success&request_token=QuNZdlk0661U8Z38dwqmVnN14Me7cmwL (Caused by NewConnectionError('<urllib3.connection.HTTPConnection object at 0x00000206D0FA1B90>: Failed to establish a new connection: [WinError 10061] No connection could be made because the target machine actively refused it'))
2025-02-24 22:25:47,120 - __main__ - ERROR - Login failed: HTTPConnectionPool(host='localhost', port=8080): Max retries exceeded with url: /apis/broker/login/zerodha?status=success&request_token=3Uzbr4qyeiICOde13Fi60aXSfr88kAti&action=login&type=login (Caused by NewConnectionError('<urllib3.connection.HTTPConnection object at 0x0000024BAD8E17D0>: Failed to establish a new connection: [WinError 10061] No connection could be made because the target machine actively refused it'))
2025-02-26 00:00:26,714 - __main__ - ERROR - Failed to generate access token: 'AccessToken' object has no attribute 'update_access_token'
2025-02-26 00:05:47,084 - __main__ - ERROR - Failed to generate access token: Token is invalid or has expired.
2025-02-26 00:53:32,375 - __main__ - ERROR - Failed to extract request token.
2025-02-28 16:52:22,567 - zerodha_kite - ERROR - Failed to log in: HTTPSConnectionPool(host='kite.zerodha.com', port=443): Max retries exceeded with url: /api/login (Caused by NameResolutionError("<urllib3.connection.HTTPSConnection object at 0x00000197A94BF190>: Failed to resolve 'kite.zerodha.com' ([Errno 11001] getaddrinfo failed)"))
2025-02-28 19:30:53,963 - app_logger - ERROR - This is an async error message.
2025-02-28 19:30:53,964 - app_logger - CRITICAL - This is an async critical message.
2025-02-28 19:31:02,150 - app_logger - ERROR - This is an async error message.
2025-02-28 19:31:02,151 - app_logger - CRITICAL - This is an async critical message.
2025-02-28 19:39:28,523 - __main__ - ERROR - This is a synchronous error message.
2025-02-28 19:39:28,523 - __main__ - CRITICAL - This is a synchronous critical message.
2025-02-28 19:39:28,529 - __main__ - ERROR - This is an async error message.
2025-02-28 19:39:28,530 - __main__ - CRITICAL - This is an async critical message.
2025-02-28 19:40:28,890 - __main__ - ERROR - This is a synchronous error message.
2025-02-28 19:40:28,890 - __main__ - CRITICAL - This is a synchronous critical message.
2025-02-28 19:40:28,896 - __main__ - ERROR - This is an async error message.
2025-02-28 19:40:28,896 - __main__ - CRITICAL - This is an async critical message.
2025-02-28 22:33:44,254 - __main__ - ERROR - This is a synchronous error message.
2025-02-28 22:33:44,259 - __main__ - CRITICAL - This is a synchronous critical message.
2025-02-28 22:33:44,267 - __main__ - ERROR - This is an async error message.
2025-02-28 22:33:44,267 - __main__ - CRITICAL - This is an async critical message.
2025-02-28 22:51:00,578 - SyncLogger - ERROR - Sync Error Message
2025-02-28 22:51:00,579 - SyncLogger - CRITICAL - Sync Critical Message
2025-02-28 22:56:51,329 - SyncLogger - ERROR - Sync Error Message
2025-02-28 22:56:51,329 - SyncLogger - CRITICAL - Sync Critical Message
2025-02-28 23:04:51,837 - test_logger - ERROR - This is an error message.
2025-02-28 23:04:51,837 - test_logger - CRITICAL - This is a critical message.
2025-02-28 23:32:38,085 - test_logger - ERROR - This is an error message.
2025-02-28 23:32:38,085 - test_logger - CRITICAL - This is a critical message.
2025-03-01 16:53:13,415 - models.base - ERROR - No market hours record found in market hours table for 2025-03-01
2025-03-01 16:53:43,424 - models.base - ERROR - No market hours record found in market hours table for 2025-03-01
2025-03-01 17:00:26,193 - models.base - ERROR - No market hours record found in market hours table for 2025-03-01
